Workbook

Sheet Dagboek macro layout
A1: Dag 1
A2: Ontbijt | G2: Middageten | M2: Avondeten | S2: Tussendoortjes | Y2: Water
A3: Product | B3: g/ml/st | C3: Kcal | D3: Eiwit | E3: Koolh. | F3: Vet | G3: Product | H3: g/ml/st | I3: Kcal | J3: Eiwit | K3: Koolh. | L3: Vet | M3: Product | N3: g/ml/st | O3: Kcal | P3: Eiwit | Q3: Koolh. | R3: Vet | S3: Product | T3: g/ml/st | U3: Kcal | V3: Eiwit | W3: Koolh. | X3: Vet | Y3: ml | Z3: Dag totaal ml
A4: Muesli bio | B4: 60 | C4: 270 | D4: 8.1 | E4: 48.6 | F4: 4.8 | G4: Groentesoep (home-made) | H4: 410 | I4: 213 | J4: 8 | K4: 29.3 | L4: 7.1 | M4: Rode bieten | N4: 250 | O4: 73 | P4: 2.2 | Q4: 15 | R4: 0.5 | S4: Koffie zwart | T4: 100 | U4: 1 | V4: 0 | W4: 0 | X4: 0 | Y4: 200
A5: Volle melk | B5: 165 | C5: 109 | D5: 5.5 | E5: 8.2 | F5: 6.1 | G5: Boterham(volkoren) | H5: 3 | I5: 228 | J5: 8 | K5: 39.9 | L5: 4.1 | M5: Rundersaucijs | N5: 70 | O5: 153 | P5: 10.7 | Q5: 1.5 | R5: 11.6 | S5: Paasstol | T5: 100 | U5: 310 | V5: 6.2 | W5: 54.2 | X5: 7.6 | Y5: 350
A6: Boterham(volkoren) | B6: 2 | C6: 152 | D6: 5.3 | E6: 26.6 | F6: 2.7 | G6: Plak kaas jong-belegen | H6: 1 | I6: 120 | J6: 20.3 | K6: 1.4 | L6: 22.6 | M6: Onbekend item (Avondeten) | N6: 214 | O6: 569 | P6: 17.1 | Q6: 64 | R6: 27.2 | Y6: 250
A7: Appelstroop | B7: 2 | C7: 5 | D7: 0 | E7: 1.2 | F7: 0 | G7: Humus-pesto | H7: 8 | I7: 52 | J7: 1.6 | K7: 2.9 | L7: 3.8 | M7: Sla melange | N7: 80 | O7: 18 | P7: 0.9 | Q7: 2.9 | R7: 0.3 | Y7: 300
A8: Honing | B8: 5 | C8: 15 | D8: 0 | E8: 3.8 | F8: 0 | G8: Honing | H8: 5 | I8: 15 | J8: 0 | K8: 3.8 | L8: 0 | Y8: 350
Y9: 150
Y10: 300
A11: Totaal | C11: =SUM(C4:C8) -> 551 | D11: 18.9 | E11: 88.4 | F11: 13.6 | G11: Totaal | I11: =SUM(I4:I8) -> 628 | J11: 37.9 | K11: 77.3 | L11: 37.6 | O11: =SUM(O4:O7) -> 813 | P11: 30.9 | Q11: 83.4 | R11: 39.6 | U11: =SUM(U4:U5) -> 311 | V11: 6.2 | W11: 54.2 | X11: 7.6 | Z11: 1900
A12: Dagtotaal | C12: =SUM(C11,I11,O11,U11) -> 2303 | D12: 93.9 | E12: 303.3 | F12: 98.4
A14: Dag 2
A15: Ontbijt | G15: Middageten | M15: Avondeten | S15: Tussendoortjes | Y15: Water
A16: Product | B16: g/ml/st | C16: Kcal | D16: Eiwit | E16: Koolh. | F16: Vet | G16: Product | H16: g/ml/st | I16: Kcal | J16: Eiwit | K16: Koolh. | L16: Vet | M16: Product | N16: g/ml/st | O16: Kcal | P16: Eiwit | Q16: Koolh. | R16: Vet | S16: Product | T16: g/ml/st | U16: Kcal | V16: Eiwit | W16: Koolh. | X16: Vet | Y16: ml | Z16: Dag totaal ml
A17: Havermout | B17: 40 | C17: 152 | D17: 6.1 | E17: 25.5 | F17: 2.9 | G17: Boterham(volkoren) | H17: 3 | I17: 228 | J17: 8 | K17: 39.9 | L17: 4.1 | M17: Pandan rijst | N17: 320 | O17: 563 | P17: 11.3 | Q17: 126.7 | R17: 1.3 | S17: Koffie zwart | T17: 100 | U17: 1 | V17: 0 | W17: 0 | X17: 0 | Y17: 350
A18: Volle melk | B18: 180 | C18: 119 | D18: 6 | E18: 8.9 | F18: 6.6 | G18: Plak kaas jong-belegen | H18: 1 | I18: 120 | J18: 20.3 | K18: 1.4 | L18: 22.6 | M18: Chinese kool | N18: 180 | O18: 31 | P18: 1.7 | Q18: 5.4 | R18: 0.3 | S18: Jodenkoek | T18: 1 | U18: 109 | V18: 1.4 | W18: 16.9 | X18: 4 | Y18: 150
A19: Rozijnen | B19: 20 | C19: 69 | D19: 0.5 | E19: 16.6 | F19: 0.1 | G19: Appelstroop | H19: 2 | I19: 5 | J19: 0 | K19: 1.2 | L19: 0 | M19: Rundergehakt | N19: 120 | O19: 89 | P19: 10 | Q19: 0 | R19: 5.4 | S19: Appelsap | T19: 150 | U19: 72 | V19: 0 | W19: 18 | X19: 0 | Y19: 150
A20: Kokos | B20: 4 | C20: 22 | D20: 0.2 | E20: 1 | F20: 1.9 | G20: Gerookte zalmsalade | H20: 30 | I20: 115 | J20: 6.6 | K20: 2.3 | L20: 8.8 | M20: Sla melange | N20: 30 | O20: 7 | P20: 0.4 | Q20: 1.1 | R20: 0.1 | S20: Naturel chips | T20: 45 | U20: 250 | V20: 3.8 | W20: 30 | X20: 12.8 | Y20: 350
A21: Noten/zaden mix | B21: 10 | C21: 44 | D21: 1.5 | E21: 2 | F21: 3.3 | G21: Haring | H21: 1 | I21: 216 | J21: 18.9 | K21: 0 | L21: 15.6 | M21: Griekse yoghurt 10% | N21: 140 | O21: 188 | P21: 7.5 | Q21: 6.6 | R21: 14.6 | Y21: 150
A22: Boterham(volkoren) | B22: 2 | C22: 152 | D22: 5.3 | E22: 26.6 | F22: 2.7 | Y22: 350
A23: Appelstroop | B23: 2 | C23: 5 | D23: 0 | E23: 1.2 | F23: 0
A24: Honing | B24: 5 | C24: 15 | D24: 0 | E24: 3.8 | F24: 0
A25: Appel | B25: 1 | C25: 15 | D25: 0.1 | E25: 3.6 | F25: 0
A26: Totaal | C26: =SUM(C17:C25) -> 593 | D26: 19.7 | E26: 89.2 | F26: 17.5 | I26: =SUM(I17:I21) -> 684 | J26: 53.8 | K26: 44.8 | L26: 51.1 | O26: =SUM(O17:O21) -> 878 | P26: 30.9 | Q26: 139.8 | R26: 21.7 | U26: =SUM(U17:U20) -> 432 | V26: 5.2 | W26: 64.9 | X26: 16.8 | Z26: 1500
A27: Dagtotaal | C27: =SUM(C26,I26,O26,U26) -> 2587 | D27: 109.6 | E27: 338.7 | F27: 107.1
A29: Dag 3
A30: Ontbijt | G30: Middageten | M30: Avondeten | S30: Tussendoortjes | Y30: Water
A31: Product | B31: g/ml/st | C31: Kcal | D31: Eiwit | E31: Koolh. | F31: Vet | G31: Product | H31: g/ml/st | I31: Kcal | J31: Eiwit | K31: Koolh. | L31: Vet | M31: Product | N31: g/ml/st | O31: Kcal | P31: Eiwit | Q31: Koolh. | R31: Vet | S31: Product | T31: g/ml/st | U31: Kcal | V31: Eiwit | W31: Koolh. | X31: Vet | Y31: ml | Z31: Dag totaal ml
A32: Muesli bio | B32: 40 | C32: 180 | D32: 10.8 | E32: 64.8 | F32: 6.4 | G32: Groentesoep (home-made) | H32: 210 | I32: 109 | J32: 4.1 | K32: 15 | L32: 3.6 | M32: Groentesoep (home-made) | N32: 210 | O32: 109 | P32: 4.1 | Q32: 15 | R32: 3.6 | S32: Koffie zwart | T32: 100 | U32: 1 | V32: 0 | W32: 0 | X32: 0 | Y32: 150
A33: Kokos | B33: 3 | C33: 16 | D33: 0.2 | E33: 0.7 | F33: 1.4 | G33: Boterham(volkoren) | H33: 2 | I33: 152 | J33: 5.3 | K33: 26.6 | L33: 2.7 | M33: Pannenkoek (ham/kaas) | N33: 350 | O33: 1200 | P33: 75.8 | Q33: 227.4 | R33: 75.8 | S33: Digestive koek | T33: 1 | U33: 70 | V33: 1.1 | W33: 10.8 | X33: 2.5 | Y33: 350
A34: Volle melk | B34: 160 | C34: 106 | D34: 5.3 | E34: 7.9 | F34: 5.9 | G34: Beenham | H34: 15 | I34: 14 | J34: 2.2 | K34: 0.1 | L34: 0.5 | M34: Tonic | N34: 200 | O34: 72 | P34: 0 | Q34: 18 | R34: 0 | S34: Appel | T34: 1 | U34: 16 | V34: 0.1 | W34: 3.8 | X34: 0 | Y34: 300
A35: Boterham(volkoren) | B35: 2 | C35: 152 | D35: 5.3 | E35: 26.6 | F35: 2.7 | G35: Gekookt ei | H35: 1 | I35: 72 | J35: 6.3 | K35: 0.5 | L35: 5 | S35: Kers/slagroom cake | T35: 1 | U35: 275 | V35: 3.4 | W35: 35.8 | X35: 13.1 | Y35: 300
A36: Appelstroop | B36: 2 | C36: 5 | D36: 0 | E36: 1.2 | F36: 0 | Y36: 200
A37: Honing | B37: 5 | C37: 15 | D37: 0 | E37: 3.8 | F37: 0 | Y37: 300
A38: Noten/zaden mix | B38: 12 | C38: 53 | D38: 1.9 | E38: 2.4 | F38: 4
A39: Totaal | C39: =SUM(C32:C38) -> 527 | D39: 23.5 | E39: 107.4 | F39: 20.4 | G39: Totaal | I39: =SUM(I32:I35) -> 347 | J39: 17.9 | K39: 42.2 | L39: 11.8 | M39: Totaal | O39: =SUM(O32:O34) -> 1381 | P39: 79.9 | Q39: 260.4 | R39: 79.4 | S39: Totaal | U39: =SUM(U32:U35) -> 362 | V39: 4.6 | W39: 50.4 | X39: 15.6 | Y39: Totaal | Z39: 1600
A40: Dagtotaal | C40: =SUM(C39,I39,O39,U39) -> 2617 | D40: 125.9 | E40: 460.4 | F40: 127.2
A42: Dag 4
A43: Ontbijt | G43: Middageten | M43: Avondeten | S43: Tussendoortjes | Y43: Water
...

Sheet Samenvatting
A1: Samenvatting voedingsdagboek
A2: Dag | B2: Kcal | C2: Eiwit (g) | D2: Koolhydraten (g) | E2: Vet (g) | F2: Water (ml)
A3: Dag 1 | B3: ='Dagboek macro layout'!C12 -> 2303 | C3: 93.9 | D3: 303.3 | E3: 98.4 | F3: 1900
A4: Dag 2 | B4: ='Dagboek macro layout'!C27 -> 2587 | C4: 109.6 | D4: 338.7 | E4: 107.1 | F4: 1500
A5: Dag 3 | B5: ='Dagboek macro layout'!C40 -> 2617 | C5: 125.9 | D5: 460.4 | E5: 127.2 | F5: 1600
A6: Dag 4 | B6: ='Dagboek macro layout'!C54 -> 1909 | C6: 64.8 | D6: 316.2 | E6: 67.7 | F6: 680
A7: Dag 5 | B7: ='Dagboek macro layout'!C65 -> 1971 | C7: 188.2 | D7: 630.6 | E7: 187.9 | F7: 1100
A8: Dag 6 | B8: ='Dagboek macro layout'!C79 -> 2378 | C8: 70.2 | D8: 262.2 | E8: 125.4 | F8: 2050
A9: Dag 7 | B9: ='Dagboek macro layout'!C90 -> 1539 | C9: 52.8 | D9: 263.5 | E9: 30.4 | F9: 1300
A10: Dag 8 | B10: ='Dagboek macro layout'!C101 -> 2095 | C10: 98.2 | D10: 268.3 | E10: 88.7 | F10: 1600
A11: Gemiddelde | B11: =AVERAGE(B3:B10) -> 2174.875 | C11: =AVERAGE(C3:C10) -> 100.45 | D11: =AVERAGE(D3:D10) -> 355.4 | E11: =AVERAGE(E3:E10) -> 104.1 | F11: =AVERAGE(F3:F10) -> 1466.25
